Workbook

Sheet Sales by Payment Method
A1: Row Labels | B1: Sum of Total Sales
A2: Cash on Delivery | B2: 2939350
A3: Credit Card | B3: 5612350
A4: Debit Card | B4: 5658300
A5: Net Banking | B5: 2027000
A6: UPI | B6: 10000200
A7: Grand Total | B7: 26237200

Sheet Project Info
A1: PROJECT INFO - E-COMMERCE SALES DASHBOARD
A3: Project Objective
A4: To analyze e-commerce sales data and create an interactive Excel dashboard that helps identify sales performance, customer order trends, product performance, regional sales, and payment method patterns.
A6: Tools & Technologies
A7: Microsoft Excel, PivotTables, PivotCharts, Excel formulas, data cleaning, data analysis, and dashboard visualization.
A9: Dataset Description
A10: Microsoft Excel, PivotTables, PivotCharts, Excel formulas, data cleaning, data analysis, and dashboard visualization.
A12: Data Cleaning & Preparation
A13: Checked the dataset for missing values, standardized inconsistent city names such as Bangalore, Vizag, and Bombay, verified the Total Sales calculations using Quantity × Unit Price, and converted Total Sales into an Excel formula for automatic calculation.
A15: Analysis Performed
A16: Analyzed sales performance by region, category, product, month, and payment method using PivotTables and PivotCharts. Also analyzed order status to understand delivered, shipped, cancelled, and returned orders.
A18: Key Performance Indicators
... A28: Data cleaning, Excel formulas, PivotTables, PivotCharts, data analysis, KPI creation, dashboard development, data visualization, and business reporting.

Sheet Sales by Product
A1: Row Labels | B1: Sum of Total Sales
A2: Headphones | B2: 3797050
A3: Keyboard | B3: 2480700
A4: Laptop | B4: 3714750
A5: Monitor | B5: 4098950
A6: Smartphone | B6: 3150100
A7: Grand Total | B7: 17241550

Sheet E-commerce Dashboard
B1: E-COMMERCE SALES DASHBOARD
B2: TOTAL SALES | D2: TOTAL ORDERS | G2: AVERAGE ORDER VALUE | J2: CANCELLED ORDERS
B3: =SUM('Raw Data'!L2:L1201) -> 26285550 | D3: =COUNTA('Raw Data'!A2:A1201) -> 1200 | G3: =AVERAGE('Raw Data'!L2:L1201) -> 21904.625 | J3: =COUNTIF('Raw Data'!K2:K1201,"Cancelled") -> 99
B4: DELIVERED ORDERS | D4: RETURNED ORDERS | G4: SHIPPED ORDERS
B5: =COUNTIF('Raw Data'!K2:K1201,"Delivered") -> 936 | D5: =COUNTIF('Raw Data'!K2:K1201,"Returned") -> 55 | G5: =COUNTIF('Raw Data'!K2:K1201,"Shipped") -> 110

Sheet Monthly Sales Trend
A1: Row Labels | B1: Sum of Total Sales
A2: Jan | B2: 2854700
A3: Feb | B3: 2293250
A4: Mar | B4: 2036600
A5: Apr | B5: 2203000
A6: May | B6: 2096950
A7: Jun | B7: 2133100
A8: Jul | B8: 2122150
A9: Aug | B9: 2047000
A10: Sep | B10: 2094500
A11: Oct | B11: 2385450
A12: Nov | B12: 2005900
A13: Dec | B13: 2012950
A14: Grand Total | B14: 26285550

Sheet Sales by Category
A1: Row Labels | B1: Sum of Total Sales
A2: Beauty | B2: 733000
A3: Electronics | B3: 19344850
A4: Fashion | B4: 1890700
A5: Home & Kitchen | B5: 2364100
A6: Sports | B6: 1952900
A7: Grand Total | B7: 26285550

Sheet Sales by Region
A3: Row Labels | B3: Sum of Total Sales
A4: East | B4: 4950900
A5: North | B5: 5579750
A6: South | B6: 10271750
A7: West | B7: 5483150
A8: Grand Total | B8: 26285550

Sheet Raw Data
A1: Order ID | B1: Customer ID | C1: Order Date | D1: Region | E1: City | F1: Category | G1: Product | H1: Quantity | I1: Unit Price | J1: Payment Method | K1: Order Status | L1: Total Sales
A2: ORD10001 | B2: CUST0088 | C2: 45757 | D2: South | E2: Vijayawada | F2: Home & Kitchen | G2: Table Lamp | H2: 1 | I2: 5500 | J2: UPI | K2: Delivered | L2: =H2*I2 -> 5500
A3: ORD10002 | B3: CUST0161 | C3: 45971 | D3: South | E3: Bengaluru | F3: Electronics | G3: Monitor | H3: 4 | I3: 47100 | J3: UPI | K3: Returned | L3: =H3*I3 -> 188400
A4: ORD10003 | B4: CUST0190 | C4: 45832 | D4: South | E4: Chennai | F4: Fashion | G4: Backpack | H4: 1 | I4: 5050 | J4: UPI | K4: Delivered | L4: =H4*I4 -> 5050
A5: ORD10004 | B5: CUST0274 | C5: 45746 | D5: North | E5: Chandigarh | F5: Fashion | G5: Backpack | H5: 3 | I5: 3950 | J5: Debit Card | K5: Delivered | L5: =H5*I5 -> 11850
A6: ORD10005 | B6: CUST0264 | C6: 45692 | D6: North | E6: Jaipur | F6: Sports | G6: Cricket Bat | H6: 2 | I6: 1450 | J6: Credit Card | K6: Delivered | L6: =H6*I6 -> 2900
A7: ORD10006 | B7: CUST0191 | C7: 45875 | D7: South | E7: Vijayawada | F7: Sports | G7: Running Shoes | H7: 2 | I7: 3450 | J7: Credit Card | K7: Delivered | L7: =H7*I7 -> 6900
A8: ORD10007 | B8: CUST0190 | C8: 45953 | D8: East | E8: Bhubaneswar | F8: Home & Kitchen | G8: Air Fryer | H8: 1 | I8: 6600 | J8: Credit Card | K8: Delivered | L8: =H8*I8 -> 6600
A9: ORD10008 | B9: CUST0157 | C9: 45672 | D9: South | E9: Hyderabad | F9: Sports | G9: Dumbbells | H9: 4 | I9: 6050 | J9: Debit Card | K9: Delivered | L9: =H9*I9 -> 24200
A10: ORD10009 | B10: CUST0392 | C10: 45820 | D10: East | E10: Guwahati | F10: Electronics | G10: Laptop | H10: 1 | I10: 26100 | J10: UPI | K10: Delivered | L10: =H10*I10 -> 26100
A11: ORD10010 | B11: CUST0033 | C11: 45705 | D11: South | E11: Chennai | F11: Beauty | G11: Moisturizer | H11: 4 | I11: 3350 | J11: Cash on Delivery | K11: Delivered | L11: =H11*I11 -> 13400
A12: ORD10011 | B12: CUST0131 | C12: 45914 | D12: West | E12: Surat | F12: Home & Kitchen | G12: Table Lamp | H12: 2 | I12: 2650 | J12: Credit Card | K12: Returned | L12: =H12*I12 -> 5300
A13: ORD10012 | B13: CUST0241 | C13: 45709 | D13: North | E13: Lucknow | F13: Beauty | G13: Moisturizer | H13: 1 | I13: 750 | J13: UPI | K13: Cancelled | L13: =H13*I13 -> 750
... A26: ORD10025 | B26: CUST0310 | C26: 45820 | D26: South | E26: Hyderabad | F26: Fashion | G26: Sneakers | H26: 1 | I26: 5450 | J26: UPI | K26: Delivered | L26: =H26*I26 -> 5450
A27: ORD10026 | C27: 45852 | D27: South | E27: Vijayawada | F27: Fashion | G27: T-Shirt | H27: 1 | I27: 2200 | J27: Debit Card | K27: Delivered | L27: =H27*I27 -> 2200
A28: ORD10027 | B28: CUST0365 | C28: 45708 | D28: North | E28: Lucknow | F28: Fashion | G28: T-Shirt | H28: 1 | I28: 3200 | J28: UPI | K28: Returned | L28: =H28*I28 -> 3200
A29: ORD10028 | B29: CUST0317 | C29: 45961 | D29: North | E29: Delhi | F29: Sports | G29: Football | H29: 2 | I29: 5300 | J29: Credit Card | K29: Delivered | L29: =H29*I29 -> 10600
A30: ORD10029 | B30: CUST0099 | C30: 45890 | D30: West | E30: Surat | F30: Home & Kitchen | G30: Water Bottle | H30: 4 | I30: 1800 | J30: Net Banking | K30: Cancelled | L30: =H30*I30 -> 7200
A31: ORD10030 | B31: CUST0416 | C31: 45818 | D31: North | E31: Delhi | F31: Sports | G31: Dumbbells | H31: 5 | I31: 5950 | J31: UPI | K31: Delivered | L31: =H31*I31 -> 29750
A32: ORD10031 | B32: CUST0431 | C32: 45999 | D32: North | E32: Lucknow | F32: Home & Kitchen | G32: Air Fryer | H32: 4 | I32: 7650 | J32: UPI | K32: Delivered | L32: =H32*I32 -> 30600
A33: ORD10032 | B33: CUST0170 | C33: 45904 | D33: South | E33: Bengaluru | F33: Home & Kitchen | G33: Water Bottle | H33: 2 | I33: 6750 | J33: Debit Card | K33: Delivered | L33: =H33*I33 -> 13500
A34: ORD10033 | B34: CUST0264 | C34: 45799 | D34: East | E34: Kolkata | F34: Home & Kitchen | G34: Air Fryer | H34: 1 | I34: 950 | J34: Debit Card | K34: Delivered | L34: =H34*I34 -> 950
A35: ORD10034 | B35: CUST0125 | C35: 45807 | D35: North | E35: Chandigarh | F35: Sports | G35: Running Shoes | H35: 1 | I35: 6000 | J35: Credit Card | K35: Delivered | L35: =H35*I35 -> 6000
A36: ORD10035 | B36: CUST0060 | C36: 45765 | D36: South | E36: Bengaluru | F36: Fashion | G36: T-Shirt | H36: 2 | I36: 2700 | J36: UPI | K36: Shipped | L36: =H36*I36 -> 5400
A37: ORD10036 | B37: CUST0269 | C37: 45781 | D37: East | E37: Guwahati | F37: Fashion | G37: Backpack | H37: 2 | I37: 4450 | J37: Debit Card | K37: Delivered | L37: =H37*I37 -> 8900
A38: ORD10037 | B38: CUST0318 | C38: 45936 | D38: West | E38: Ahmedabad | F38: Beauty | G38: Moisturizer | H38: 2 | I38: 2300 | J38: UPI | K38: Delivered | L38: =H38*I38 -> 4600
A39: ORD10038 | B39: CUST0089 | C39: 45894 | D39: North | E39: Jaipur | F39: Home & Kitchen | G39: Cookware Set | H39: 1 | I39: 8250 | J39: UPI | K39: Delivered | L39: =H39*I39 -> 8250
... A199: ORD10198 | B199: CUST0436 | C199: 45671 | D199: West | E199: Pune | F199: Home & Kitchen | G199: Air Fryer | H199: 3 | I199: 7950 | J199: Cash on Delivery | K199: Shipped | L199: =H199*I199 -> 23850
A200: ORD10199 | B200: CUST0025 | C200: 45938 | D200: South | E200: Chennai | F200: Electronics | G200: Headphones | H200: 1 | I200: 45400 | K200: Delivered | L200: =H200*I200 -> 45400
A201: ORD10200 | B201: CUST0425 | C201: 45682 | D201: East | E201: Bhubaneswar | F201: Home & Kitchen | G201: Mixer Grinder | H201: 3 | I201: 1450 | J201: Cash on Delivery | K201: Delivered | L201: =H201*I201 -> 4350
A202: ORD10201 | B202: CUST0128 | C202: 45753 | D202: South | E202: Bengaluru | F202: Fashion | G202: Jeans | H202: 1 | I202: 4250 | J202: UPI | K202: Delivered | L202: =H202*I202 -> 4250
A203: ORD10202 | B203: CUST0151 | C203: 45944 | D203: North | E203: Bengaluru | F203: Fashion | G203: Backpack | H203: 1 | I203: 6850 | J203: UPI | K203: Delivered | L203: =H203*I203 -> 6850
A204: ORD10203 | B204: CUST0083 | C204: 45756 | D204: South | E204: Hyderabad | F204: Electronics | G204: Monitor | H204: 5 | I204: 4450 | J204: UPI | K204: Delivered | L204: =H204*I204 -> 22250
A205: ORD10204 | B205: CUST0040 | C205: 45930 | D205: South | E205: Chennai | F205: Electronics | G205: Keyboard | H205: 2 | I205: 12150 | J205: Debit Card | K205: Delivered | L205: =H205*I205 -> 24300
A206: ORD10205 | B206: CUST0191 | C206: 45719 | D206: South | E206: Vijayawada | F206: Electronics | G206: Keyboard | H206: 3 | I206: 42850 | J206: Debit Card | K206: Shipped | L206: =H206*I206 -> 128550
A207: ORD10206 | B207: CUST0183 | C207: 45719 | D207: South | E207: Vijayawada | F207: Fashion | G207: Sneakers | H207: 1 | I207: 4050 | J207: Credit Card | K207: Returned | L207: =H207*I207 -> 4050
A208: ORD10207 | B208: CUST0213 | C208: 45838 | D208: West | E208: Pune | F208: Home & Kitchen | G208: Table Lamp | H208: 2 | I208: 1900 | J208: UPI | K208: Shipped | L208: =H208*I208 -> 3800
A209: ORD10208 | B209: CUST0183 | C209: 45774 | D209: South | E209: Hyderabad | F209: Beauty | G209: Hair Dryer | H209: 2 | I209: 750 | J209: Credit Card | K209: Shipped | L209: =H209*I209 -> 1500
A210: ORD10209 | B210: CUST0422 | C210: 45699 | D210: East | E210: Guwahati | F210: Home & Kitchen | G210: Cookware Set | H210: 1 | I210: 6700 | J210: Credit Card | K210: Delivered | L210: =H210*I210 -> 6700
A211: ORD10210 | B211: CUST0029 | C211: 45754 | D211: South | E211: Vijayawada | F211: Beauty | G211: Hair Dryer | H211: 1 | I211: 4000 | J211: Debit Card | K211: Delivered | L211: =H211*I211 -> 4000
...

Sheet Dataset Info
A1: Item | B1: Details
A2: Project | B2: E-commerce Sales Dashboard
A3: Dataset | B3: Synthetic practice dataset
A4: Rows | B4: 1200
A5: Columns | B5: 12
A6: Purpose | B6: Cleaning, PivotTables, KPIs, dashboard and business insights
A7: Note | B7: Created for portfolio practice; not real company data.
